Object {
  "exitCode": 1,
  "stderr": "",
  "stdout": "::debug::starting to run should fail
::error title=should fail,file=tests/example.mjs,line=5,col=3::Error [ERR_TEST_FAILURE]: The expression evaluated to a falsy value:%0A%0A  assert(false)%0A%0A    at AsyncResource.runInAsyncScope (node:async_hooks:206:9) {%0A  code: 'ERR_TEST_FAILURE',%0A  failureType: 'testCodeFailure',%0A  cause: AssertionError [ERR_ASSERTION]: The expression evaluated to a falsy value:%0A  %0A    assert(false)%0A  %0A      at TestContext.<anonymous> (file://CWD/tests/example.mjs:5:3)%0A      at Test.runInAsyncScope (node:async_hooks:206:9)%0A      at Test.run (node:internal/test_runner/test:796:25)%0A      at Test.processPendingSubtests (node:internal/test_runner/test:526:18)%0A      at node:internal/test_runner/harness:255:12%0A      at node:internal/process/task_queues:140:7%0A      at AsyncResource.runInAsyncScope (node:async_hooks:206:9)%0A      at AsyncResource.runMicrotask (node:internal/process/task_queues:137:8) {%0A    generatedMessage: true,%0A    code: 'ERR_ASSERTION',%0A    actual: false,%0A    expected: true,%0A    operator: '=='%0A  }%0A}
::debug::starting to run should pass
::debug::completed running should pass
::group::Test results (1 passed, 1 failed)
::notice::Total Tests: 2%0ASuites 📂: 0%0APassed ✅: 1%0AFailed ❌: 1%0ACanceled 🚫: 0%0ASkipped ⏭️: 0%0ATodo 📝: 0%0ADuration 🕐: *ms
::endgroup::
",
}